Workbook

Sheet Accueil
A1: AUTODIAGNOSTIC ISO/IEC 27001:2022
A3: Établissement :
A4: Responsable du SMSI :
A6: Date de l'autodiagnostic :
A7: Équipe d'autodiagnostic :
A9: Instructions : renseigner la colonne « Évaluation » de l'onglet « 1. Évaluation » pour chacun des 93 contrôles, en choisissant un niveau dans la liste déroulante (Insuffisant / Informel / Convaincant / Optimisé). Les taux de conformité et les graphiques de l'onglet « 2. Tableau de bord » se calculent automatiquement.

Sheet Légende
A1: ÉCHELLE DE MATURITÉ
A3: Niveau | B3: Taux de conformité associé | C3: Définition
A4: Insuffisant | B4: 0.15 | C4: Le contrôle n'est pas mis en œuvre, ou son existence n'est pas constatée. Aucune pratique, même informelle, n'est observée.
A5: Informel | B5: 0.5 | C5: Le contrôle est appliqué de façon ponctuelle et non formalisée (pas de procédure écrite, dépendant de personnes plutôt que d'un processus).
A6: Convaincant | B6: 0.67 | C6: Le contrôle est formalisé, documenté et appliqué de façon régulière, mais sans pilotage centralisé ni amélioration continue systématique.
A7: Optimisé | B7: 1 | C7: Le contrôle est formalisé, appliqué, mesuré par des indicateurs et fait l'objet d'une amélioration continue pilotée.
A9: Structure de l'Annexe A ISO/IEC 27001:2022 (93 contrôles)
A10: Thème | B10: Nombre de contrôles | C10: Domaine
A11: A.5 Organisationnel | B11: 37 | C11: Gouvernance, politiques, gestion des risques, fournisseurs, incidents, continuité, conformité
A12: A.6 Personnes | B12: 8 | C12: Vérifications, sensibilisation, conditions d'emploi, travail à distance
A13: A.7 Physique | B13: 14 | C13: Zones sécurisées, protection des équipements, accès physique
A14: A.8 Technologique | B14: 34 | C14: Contrôle d'accès, cryptographie, opérations, développement, gestion des vulnérabilités

Sheet 1. Évaluation
A1: AUTODIAGNOSTIC — LES 93 CONTRÔLES DE L'ANNEXE A ISO/IEC 27001:2022
A2: Choisir un niveau dans la colonne « Évaluation » (liste déroulante) pour chaque contrôle. Le taux se calcule automatiquement.
A4: Thème | B4: Sous-thème | C4: Code | D4: Contrôle | E4: Évaluation | F4: Taux
A5: A.5 Organisationnel | B5: Politiques et gouvernance | C5: A.5.1 | D5: Politiques de sécurité de l'information | E5: Insuffisant | F5: =IFERROR(VLOOKUP(E5,Légende!$A$4:$B$7,2,FALSE()),"") -> 0.15
A6: A.5 Organisationnel | B6: Politiques et gouvernance | C6: A.5.2 | D6: Rôles et responsabilités en matière de sécurité de l'information | E6: Insuffisant | F6: =IFERROR(VLOOKUP(E6,Légende!$A$4:$B$7,2,FALSE()),"") -> 0.15
A7: A.5 Organisationnel | B7: Politiques et gouvernance | C7: A.5.3 | D7: Séparation des tâches | E7: Insuffisant | F7: =IFERROR(VLOOKUP(E7,Légende!$A$4:$B$7,2,FALSE()),"") -> 0.15
A8: A.5 Organisationnel | B8: Politiques et gouvernance | C8: A.5.4 | D8: Responsabilités de la direction | F8: =IFERROR(VLOOKUP(E8,Légende!$A$4:$B$7,2,FALSE()),"")
A9: A.5 Organisationnel | B9: Politiques et gouvernance | C9: A.5.5 | D9: Contact avec les autorités | F9: =IFERROR(VLOOKUP(E9,Légende!$A$4:$B$7,2,FALSE()),"")
A10: A.5 Organisationnel | B10: Politiques et gouvernance | C10: A.5.6 | D10: Contact avec des groupes d'intérêt spécial | F10: =IFERROR(VLOOKUP(E10,Légende!$A$4:$B$7,2,FALSE()),"")
A11: A.5 Organisationnel | B11: Gestion de l'information | C11: A.5.7 | D11: Renseignement sur les menaces | E11: Informel | F11: =IFERROR(VLOOKUP(E11,Légende!$A$4:$B$7,2,FALSE()),"") -> 0.5
A12: A.5 Organisationnel | B12: Gestion de l'information | C12: A.5.8 | D12: Sécurité de l'information dans la gestion de projet | F12: =IFERROR(VLOOKUP(E12,Légende!$A$4:$B$7,2,FALSE()),"")
A13: A.5 Organisationnel | B13: Gestion de l'information | C13: A.5.9 | D13: Inventaire de l'information et des autres actifs associés | F13: =IFERROR(VLOOKUP(E13,Légende!$A$4:$B$7,2,FALSE()),"")
A14: A.5 Organisationnel | B14: Gestion de l'information | C14: A.5.10 | D14: Utilisation acceptable de l'information et des autres actifs associés | E14: Insuffisant | F14: =IFERROR(VLOOKUP(E14,Légende!$A$4:$B$7,2,FALSE()),"") -> 0.15
A15: A.5 Organisationnel | B15: Gestion de l'information | C15: A.5.11 | D15: Restitution des actifs | F15: =IFERROR(VLOOKUP(E15,Légende!$A$4:$B$7,2,FALSE()),"")
A16: A.5 Organisationnel | B16: Gestion de l'information | C16: A.5.12 | D16: Classification de l'information | F16: =IFERROR(VLOOKUP(E16,Légende!$A$4:$B$7,2,FALSE()),"")
A17: A.5 Organisationnel | B17: Gestion de l'information | C17: A.5.13 | D17: Étiquetage de l'information | F17: =IFERROR(VLOOKUP(E17,Légende!$A$4:$B$7,2,FALSE()),"")
A18: A.5 Organisationnel | B18: Gestion de l'information | C18: A.5.14 | D18: Transfert de l'information | F18: =IFERROR(VLOOKUP(E18,Légende!$A$4:$B$7,2,FALSE()),"")
A19: A.5 Organisationnel | B19: Contrôle d'accès et identité | C19: A.5.15 | D19: Contrôle d'accès | E19: Convaincant | F19: =IFERROR(VLOOKUP(E19,Légende!$A$4:$B$7,2,FALSE()),"") -> 0.67
A20: A.5 Organisationnel | B20: Contrôle d'accès et identité | C20: A.5.16 | D20: Gestion des identités | F20: =IFERROR(VLOOKUP(E20,Légende!$A$4:$B$7,2,FALSE()),"")
A21: A.5 Organisationnel | B21: Contrôle d'accès et identité | C21: A.5.17 | D21: Informations d'authentification | F21: =IFERROR(VLOOKUP(E21,Légende!$A$4:$B$7,2,FALSE()),"")
A22: A.5 Organisationnel | B22: Contrôle d'accès et identité | C22: A.5.18 | D22: Droits d'accès | E22: Convaincant | F22: =IFERROR(VLOOKUP(E22,Légende!$A$4:$B$7,2,FALSE()),"") -> 0.67
A23: A.5 Organisationnel | B23: Gestion des fournisseurs | C23: A.5.19 | D23: Sécurité de l'information dans les relations fournisseurs | E23: Informel | F23: =IFERROR(VLOOKUP(E23,Légende!$A$4:$B$7,2,FALSE()),"") -> 0.5
A24: A.5 Organisationnel | B24: Gestion des fournisseurs | C24: A.5.20 | D24: Traitement de la sécurité de l'information dans les accords fournisseurs | F24: =IFERROR(VLOOKUP(E24,Légende!$A$4:$B$7,2,FALSE()),"")
A25: A.5 Organisationnel | B25: Gestion des fournisseurs | C25: A.5.21 | D25: Gestion de la sécurité de l'information dans la chaîne d'approvisionnement TIC | E25: Convaincant | F25: =IFERROR(VLOOKUP(E25,Légende!$A$4:$B$7,2,FALSE()),"") -> 0.67
A26: A.5 Organisationnel | B26: Gestion des fournisseurs | C26: A.5.22 | D26: Surveillance, revue et gestion des changements des services fournisseurs | F26: =IFERROR(VLOOKUP(E26,Légende!$A$4:$B$7,2,FALSE()),"")
A27: A.5 Organisationnel | B27: Gestion des fournisseurs | C27: A.5.23 | D27: Sécurité de l'information pour l'utilisation des services cloud | F27: =IFERROR(VLOOKUP(E27,Légende!$A$4:$B$7,2,FALSE()),"")
A28: A.5 Organisationnel | B28: Incidents et continuité | C28: A.5.24 | D28: Planification et préparation de la gestion des incidents | E28: Informel | F28: =IFERROR(VLOOKUP(E28,Légende!$A$4:$B$7,2,FALSE()),"") -> 0.5
A29: A.5 Organisationnel | B29: Incidents et continuité | C29: A.5.25 | D29: Évaluation et décision sur les événements de sécurité de l'information | F29: =IFERROR(VLOOKUP(E29,Légende!$A$4:$B$7,2,FALSE()),"")
A30: A.5 Organisationnel | B30: Incidents et continuité | C30: A.5.26 | D30: Réponse aux incidents de sécurité de l'information | F30: =IFERROR(VLOOKUP(E30,Légende!$A$4:$B$7,2,FALSE()),"")
A31: A.5 Organisationnel | B31: Incidents et continuité | C31: A.5.27 | D31: Apprentissage des incidents de sécurité de l'information | E31: Insuffisant | F31: =IFERROR(VLOOKUP(E31,Légende!$A$4:$B$7,2,FALSE()),"") -> 0.15
A32: A.5 Organisationnel | B32: Incidents et continuité | C32: A.5.28 | D32: Collecte de preuves | F32: =IFERROR(VLOOKUP(E32,Légende!$A$4:$B$7,2,FALSE()),"")
A33: A.5 Organisationnel | B33: Incidents et continuité | C33: A.5.29 | D33: Sécurité de l'information pendant une perturbation | F33: =IFERROR(VLOOKUP(E33,Légende!$A$4:$B$7,2,FALSE()),"")
A34: A.5 Organisationnel | B34: Incidents et continuité | C34: A.5.30 | D34: Préparation des TIC pour la continuité d'activité | E34: Insuffisant | F34: =IFERROR(VLOOKUP(E34,Légende!$A$4:$B$7,2,FALSE()),"") -> 0.15
A35: A.5 Organisationnel | B35: Conformité et juridique | C35: A.5.31 | D35: Exigences légales, statutaires, réglementaires et contractuelles | E35: Informel | F35: =IFERROR(VLOOKUP(E35,Légende!$A$4:$B$7,2,FALSE()),"") -> 0.5
A36: A.5 Organisationnel | B36: Conformité et juridique | C36: A.5.32 | D36: Droits de propriété intellectuelle | E36: Informel | F36: =IFERROR(VLOOKUP(E36,Légende!$A$4:$B$7,2,FALSE()),"") -> 0.5
A37: A.5 Organisationnel | B37: Conformité et juridique | C37: A.5.33 | D37: Protection des enregistrements | F37: =IFERROR(VLOOKUP(E37,Légende!$A$4:$B$7,2,FALSE()),"")
A38: A.5 Organisationnel | B38: Conformité et juridique | C38: A.5.34 | D38: Protection de la vie privée et des données personnelles | E38: Informel | F38: =IFERROR(VLOOKUP(E38,Légende!$A$4:$B$7,2,FALSE()),"") -> 0.5
A39: A.5 Organisationnel | B39: Conformité et juridique | C39: A.5.35 | D39: Revue indépendante de la sécurité de l'information | F39: =IFERROR(VLOOKUP(E39,Légende!$A$4:$B$7,2,FALSE()),"")
A40: A.5 Organisationnel | B40: Conformité et juridique | C40: A.5.36 | D40: Conformité aux politiques, règles et normes de sécurité | F40: =IFERROR(VLOOKUP(E40,Légende!$A$4:$B$7,2,FALSE()),"")
A41: A.5 Organisationnel | B41: Conformité et juridique | C41: A.5.37 | D41: Procédures opérationnelles documentées | E41: Insuffisant | F41: =IFERROR(VLOOKUP(E41,Légende!$A$4:$B$7,2,FALSE()),"") -> 0.15
...

Sheet 2. Tableau de bord
A3: 1. Synthèse par thème
A4: Thème | B4: Nombre de contrôles | C4: Nombre évalués | D4: Taux de conformité moyen
A5: A.5 Organisationnel | B5: =COUNTIF('1. Évaluation'!A5:A97,A5) -> 37 | C5: =COUNTIFS('1. Évaluation'!A5:A97,A5,'1. Évaluation'!E5:E97,"<>") -> 16 | D5: =IFERROR(AVERAGEIF('1. Évaluation'!A5:A97,A5,'1. Évaluation'!F5:F97),"") -> 0.37875
A6: A.6 Personnes | B6: =COUNTIF('1. Évaluation'!A5:A97,A6) -> 8 | C6: =COUNTIFS('1. Évaluation'!A5:A97,A6,'1. Évaluation'!E5:E97,"<>") -> 0 | D6: =IFERROR(AVERAGEIF('1. Évaluation'!A5:A97,A6,'1. Évaluation'!F5:F97),"")
A7: A.7 Physique | B7: =COUNTIF('1. Évaluation'!A5:A97,A7) -> 14 | C7: =COUNTIFS('1. Évaluation'!A5:A97,A7,'1. Évaluation'!E5:E97,"<>") -> 11 | D7: =IFERROR(AVERAGEIF('1. Évaluation'!A5:A97,A7,'1. Évaluation'!F5:F97),"") -> 0.49818182
A8: A.8 Technologique | B8: =COUNTIF('1. Évaluation'!A5:A97,A8) -> 34 | C8: =COUNTIFS('1. Évaluation'!A5:A97,A8,'1. Évaluation'!E5:E97,"<>") -> 15 | D8: =IFERROR(AVERAGEIF('1. Évaluation'!A5:A97,A8,'1. Évaluation'!F5:F97),"") -> 0.50933333
A10: Moyenne générale | D10: =IFERROR(AVERAGE('1. Évaluation'!F5:F97),"") -> 0.45666667
A12: 2. Synthèse par sous-thème
A13: Thème | B13: Sous-thème | C13: Nombre de contrôles | D13: Taux de conformité moyen
A14: A.5 Organisationnel | B14: Politiques et gouvernance | C14: 6 | D14: =IFERROR(AVERAGE('1. Évaluation'!F5:F10),"") -> 0.15
A15: A.5 Organisationnel | B15: Gestion de l'information | C15: 8 | D15: =IFERROR(AVERAGE('1. Évaluation'!F11:F18),"") -> 0.325
A16: A.5 Organisationnel | B16: Contrôle d'accès et identité | C16: 4 | D16: =IFERROR(AVERAGE('1. Évaluation'!F19:F22),"") -> 0.67
A17: A.5 Organisationnel | B17: Gestion des fournisseurs | C17: 5 | D17: =IFERROR(AVERAGE('1. Évaluation'!F23:F27),"") -> 0.585
A18: A.5 Organisationnel | B18: Incidents et continuité | C18: 7 | D18: =IFERROR(AVERAGE('1. Évaluation'!F28:F34),"") -> 0.26666667
A19: A.5 Organisationnel | B19: Conformité et juridique | C19: 7 | D19: =IFERROR(AVERAGE('1. Évaluation'!F35:F41),"") -> 0.4125
A20: A.6 Personnes | B20: Personnes | C20: 8 | D20: =IFERROR(AVERAGE('1. Évaluation'!F42:F49),"")
A21: A.7 Physique | B21: Sécurité des zones | C21: 7 | D21: =IFERROR(AVERAGE('1. Évaluation'!F50:F56),"") -> 0.585
A22: A.7 Physique | B22: Sécurité des équipements | C22: 7 | D22: =IFERROR(AVERAGE('1. Évaluation'!F57:F63),"") -> 0.44857143
A23: A.8 Technologique | B23: Terminaux et accès | C23: 5 | D23: =IFERROR(AVERAGE('1. Évaluation'!F64:F68),"") -> 0.4975
A24: A.8 Technologique | B24: Configuration et vulnérabilités | C24: 5 | D24: =IFERROR(AVERAGE('1. Évaluation'!F69:F73),"") -> 0.325
A25: A.8 Technologique | B25: Protection des données | C25: 4 | D25: =IFERROR(AVERAGE('1. Évaluation'!F74:F77),"") -> 0.325
A26: A.8 Technologique | B26: Journalisation et surveillance | C26: 2 | D26: =IFERROR(AVERAGE('1. Évaluation'!F78:F79),"") -> 0.67
A27: A.8 Technologique | B27: Sécurité opérationnelle et réseau | C27: 6 | D27: =IFERROR(AVERAGE('1. Évaluation'!F80:F85),"") -> 0.61333333
A28: A.8 Technologique | B28: Sécurité web et cryptographie | C28: 2 | D28: =IFERROR(AVERAGE('1. Évaluation'!F86:F87),"") -> 0.5
A29: A.8 Technologique | B29: Sécurité du développement | C29: 10 | D29: =IFERROR(AVERAGE('1. Évaluation'!F88:F97),"") -> 0.67
A31: 3. Distribution des niveaux de maturité
A32: Niveau | B32: Nombre de contrôles
A33: Insuffisant | B33: =COUNTIF('1. Évaluation'!E5:E97,A33) -> 12
A34: Informel | B34: =COUNTIF('1. Évaluation'!E5:E97,A34) -> 16
A35: Convaincant | B35: =COUNTIF('1. Évaluation'!E5:E97,A35) -> 14
A36: Optimisé | B36: =COUNTIF('1. Évaluation'!E5:E97,A36) -> 0
